Workbook

Sheet 完成情况清单
A1: ASPICE 流程认证文档完成情况清单
A2: 填写说明：通过下拉框维护是否适用、完成状态和评审状态；完成度及汇总统计自动计算。
A4: 序号 | B4: 阶段 | C4: 过程域 | D4: 文档/工作产品 | E4: 周期/触发条件 | F4: 完成状态 | G4: 完成度 | H4: 责任人 | I4: 计划完成日期 | J4: 实际完成日期 | K4: 版本 | L4: 评审状态 | M4: 证据/存放路径 | N4: 备注
A5: 1 | B5: 项目初期 | C5: MAN.3 | D5: 项目可行性分析报告 | F5: 未开始 | G5: =IF(F5="不适用","",IF(F5="已完成",1,0)) -> 0 | L5: 未评审
A6: 2 | D6: 项目管理计划 | F6: 未开始 | G6: =IF(F6="不适用","",IF(F6="已完成",1,0)) -> 0 | L6: 未评审
A7: 3 | D7: 项目里程碑计划 | F7: 未开始 | G7: =IF(F7="不适用","",IF(F7="已完成",1,0)) -> 0 | L7: 未评审
A8: 4 | D8: 项目进度计划 | F8: 未开始 | G8: =IF(F8="不适用","",IF(F8="已完成",1,0)) -> 0 | L8: 未评审
A9: 5 | D9: 干系人清单（含职责、权限、项目组织架构） | F9: 未开始 | G9: =IF(F9="不适用","",IF(F9="已完成",1,0)) -> 0 | L9: 未评审
A10: 6 | D10: 人员技能矩阵 | F10: 未开始 | G10: =IF(F10="不适用","",IF(F10="已完成",1,0)) -> 0 | L10: 未评审
A11: 7 | D11: 项目成员培训计划 | F11: 未开始 | G11: =IF(F11="不适用","",IF(F11="已完成",1,0)) -> 0 | L11: 未评审
A12: 8 | D12: 功能责任计划 | F12: 未开始 | G12: =IF(F12="不适用","",IF(F12="已完成",1,0)) -> 0 | L12: 未评审
A13: 9 | D13: 工具清单 | F13: 未开始 | G13: =IF(F13="不适用","",IF(F13="已完成",1,0)) -> 0 | L13: 未评审
A14: 10 | D14: 项目管理计划评审检查单 | F14: 未开始 | G14: =IF(F14="不适用","",IF(F14="已完成",1,0)) -> 0 | L14: 未评审
A15: 11 | D15: 项目进度计划评审检查单 | F15: 未开始 | G15: =IF(F15="不适用","",IF(F15="已完成",1,0)) -> 0 | L15: 未评审
A16: 12 | D16: 可行性分析报告评审检查单 | F16: 未开始 | G16: =IF(F16="不适用","",IF(F16="已完成",1,0)) -> 0 | L16: 未评审
A17: 13 | C17: SUP.1 | D17: 质量保证计划 | F17: 未开始 | G17: =IF(F17="不适用","",IF(F17="已完成",1,0)) -> 0 | L17: 未评审
A18: 14 | D18: 质量保证计划评审检查单 | F18: 未开始 | G18: =IF(F18="不适用","",IF(F18="已完成",1,0)) -> 0 | L18: 未评审
A19: 15 | D19: 评审计划 | F19: 未开始 | G19: =IF(F19="不适用","",IF(F19="已完成",1,0)) -> 0 | L19: 未评审
A20: 16 | C20: SUP.8 | D20: 配置管理计划 | F20: 未开始 | G20: =IF(F20="不适用","",IF(F20="已完成",1,0)) -> 0 | L20: 未评审
A21: 17 | D21: 配置管理计划评审检查单 | F21: 未开始 | G21: =IF(F21="不适用","",IF(F21="已完成",1,0)) -> 0 | L21: 未评审
A22: 18 | D22: 配置项清单 | F22: 未开始 | G22: =IF(F22="不适用","",IF(F22="已完成",1,0)) -> 0 | L22: 未评审
A23: 19 | D23: 配置项清单评审检查单 | F23: 未开始 | G23: =IF(F23="不适用","",IF(F23="已完成",1,0)) -> 0 | L23: 未评审
A24: 20 | D24: 配置项及权限表 | F24: 未开始 | G24: =IF(F24="不适用","",IF(F24="已完成",1,0)) -> 0 | L24: 未评审
A25: 21 | C25: SUP.9 | D25: 问题解决管理计划 | F25: 未开始 | G25: =IF(F25="不适用","",IF(F25="已完成",1,0)) -> 0 | L25: 未评审
A26: 22 | D26: 问题解决管理计划评审检查单 | F26: 未开始 | G26: =IF(F26="不适用","",IF(F26="已完成",1,0)) -> 0 | L26: 未评审
A27: 23 | C27: SUP.10 | D27: 变更管理计划 | F27: 未开始 | G27: =IF(F27="不适用","",IF(F27="已完成",1,0)) -> 0 | L27: 未评审
A28: 24 | D28: 变更管理计划评审检查单 | F28: 未开始 | G28: =IF(F28="不适用","",IF(F28="已完成",1,0)) -> 0 | L28: 未评审
A29: 25 | C29: SYS.1～SYS.3、SWE.1～SWE.3 | D29: 需求分析策略 | F29: 未开始 | G29: =IF(F29="不适用","",IF(F29="已完成",1,0)) -> 0 | L29: 未评审
A30: 26 | D30: 架构设计策略 | F30: 未开始 | G30: =IF(F30="不适用","",IF(F30="已完成",1,0)) -> 0 | L30: 未评审
A31: 27 | D31: 详细设计策略 | F31: 未开始 | G31: =IF(F31="不适用","",IF(F31="已完成",1,0)) -> 0 | L31: 未评审
A32: 28 | D32: 策略评审检查单 | F32: 未开始 | G32: =IF(F32="不适用","",IF(F32="已完成",1,0)) -> 0 | L32: 未评审
A33: 29 | B33: 项目执行期 | C33: SYS.1 | D33: 涉众需求清单 | F33: 未开始 | G33: =IF(F33="不适用","",IF(F33="已完成",1,0)) -> 0 | L33: 未评审
A34: 30 | D34: 干系人沟通记录 | F34: 未开始 | G34: =IF(F34="不适用","",IF(F34="已完成",1,0)) -> 0 | L34: 未评审
A35: 31 | C35: SYS.2 | D35: 系统需求规格说明书 | F35: 未开始 | G35: =IF(F35="不适用","",IF(F35="已完成",1,0)) -> 0 | L35: 未评审
A36: 32 | D36: 系统需求与功能需求追溯 | F36: 未开始 | G36: =IF(F36="不适用","",IF(F36="已完成",1,0)) -> 0 | L36: 未评审
A37: 33 | D37: 系统需求评审检查单 | F37: 未开始 | G37: =IF(F37="不适用","",IF(F37="已完成",1,0)) -> 0 | L37: 未评审
A38: 34 | C38: SYS.3 | D38: 系统架构设计说明书 | F38: 未开始 | G38: =IF(F38="不适用","",IF(F38="已完成",1,0)) -> 0 | L38: 未评审
A39: 35 | D39: 系统架构要素与系统需求追溯 | F39: 未开始 | G39: =IF(F39="不适用","",IF(F39="已完成",1,0)) -> 0 | L39: 未评审
A40: 36 | D40: 系统架构设计评审检查单 | F40: 未开始 | G40: =IF(F40="不适用","",IF(F40="已完成",1,0)) -> 0 | L40: 未评审
A41: 37 | C41: SWE.1 | D41: 软件需求规格说明书 | F41: 未开始 | G41: =IF(F41="不适用","",IF(F41="已完成",1,0)) -> 0 | L41: 未评审
...

Sheet 汇总统计
A1: ASPICE 文档完成情况汇总
A3: 指标 | B3: 总项数 | C3: 已完成 | D3: 进行中 | E3: 待评审 | F3: 未开始 | G3: 不适用 | H3: 总体完成率
A4: 全部过程域 | B4: =COUNTA(完成情况清单!$D$5:$D$102) -> 98 | C4: =COUNTIF(完成情况清单!$F$5:$F$102,"已完成") -> 0 | D4: =COUNTIF(完成情况清单!$F$5:$F$102,"进行中") -> 0 | E4: =COUNTIF(完成情况清单!$F$5:$F$102,"待评审") -> 0 | F4: =COUNTIF(完成情况清单!$F$5:$F$102,"未开始") -> 98 | G4: =COUNTIF(完成情况清单!$F$5:$F$102,"不适用") -> 0 | H4: =IFERROR(AVERAGE(完成情况清单!$G$5:$G$102),0) -> 0
A7: 阶段 | B7: 文档项数 | C7: 已完成 | D7: 未完成 | E7: 完成率
A8: 项目初期 | B8: =COUNTIF(统计辅助!$B$2:$B$99,A8) -> 28 | C8: =COUNTIFS(统计辅助!$B$2:$B$99,A8,完成情况清单!$F$5:$F$102,"已完成") -> 0 | D8: =B8-C8-COUNTIFS(统计辅助!$B$2:$B$99,A8,完成情况清单!$F$5:$F$102,"不适用") -> 28 | E8: =IFERROR(C8/(C8+D8),0) -> 0
A9: 项目执行期 | B9: =COUNTIF(统计辅助!$B$2:$B$99,A9) -> 50 | C9: =COUNTIFS(统计辅助!$B$2:$B$99,A9,完成情况清单!$F$5:$F$102,"已完成") -> 0 | D9: =B9-C9-COUNTIFS(统计辅助!$B$2:$B$99,A9,完成情况清单!$F$5:$F$102,"不适用") -> 50 | E9: =IFERROR(C9/(C9+D9),0) -> 0
A10: 周期性/不固定任务 | B10: =COUNTIF(统计辅助!$B$2:$B$99,A10) -> 20 | C10: =COUNTIFS(统计辅助!$B$2:$B$99,A10,完成情况清单!$F$5:$F$102,"已完成") -> 0 | D10: =B10-C10-COUNTIFS(统计辅助!$B$2:$B$99,A10,完成情况清单!$F$5:$F$102,"不适用") -> 20 | E10: =IFERROR(C10/(C10+D10),0) -> 0
A13: 过程域 | B13: 文档项数 | C13: 已完成 | D13: 未完成 | E13: 完成率
A14: MAN.3 | B14: =COUNTIF(统计辅助!$C$2:$C$99,A14) -> 16 | C14: =COUNTIFS(统计辅助!$C$2:$C$99,A14,完成情况清单!$F$5:$F$102,"已完成") -> 0 | D14: =B14-C14-COUNTIFS(统计辅助!$C$2:$C$99,A14,完成情况清单!$F$5:$F$102,"不适用") -> 16 | E14: =IFERROR(C14/(C14+D14),0) -> 0
A15: SUP.1 | B15: =COUNTIF(统计辅助!$C$2:$C$99,A15) -> 7 | C15: =COUNTIFS(统计辅助!$C$2:$C$99,A15,完成情况清单!$F$5:$F$102,"已完成") -> 0 | D15: =B15-C15-COUNTIFS(统计辅助!$C$2:$C$99,A15,完成情况清单!$F$5:$F$102,"不适用") -> 7 | E15: =IFERROR(C15/(C15+D15),0) -> 0
A16: SUP.8 | B16: =COUNTIF(统计辅助!$C$2:$C$99,A16) -> 8 | C16: =COUNTIFS(统计辅助!$C$2:$C$99,A16,完成情况清单!$F$5:$F$102,"已完成") -> 0 | D16: =B16-C16-COUNTIFS(统计辅助!$C$2:$C$99,A16,完成情况清单!$F$5:$F$102,"不适用") -> 8 | E16: =IFERROR(C16/(C16+D16),0) -> 0
A17: SUP.9 | B17: =COUNTIF(统计辅助!$C$2:$C$99,A17) -> 9 | C17: =COUNTIFS(统计辅助!$C$2:$C$99,A17,完成情况清单!$F$5:$F$102,"已完成") -> 0 | D17: =B17-C17-COUNTIFS(统计辅助!$C$2:$C$99,A17,完成情况清单!$F$5:$F$102,"不适用") -> 9 | E17: =IFERROR(C17/(C17+D17),0) -> 0
A18: SUP.10 | B18: =COUNTIF(统计辅助!$C$2:$C$99,A18) -> 4 | C18: =COUNTIFS(统计辅助!$C$2:$C$99,A18,完成情况清单!$F$5:$F$102,"已完成") -> 0 | D18: =B18-C18-COUNTIFS(统计辅助!$C$2:$C$99,A18,完成情况清单!$F$5:$F$102,"不适用") -> 4 | E18: =IFERROR(C18/(C18+D18),0) -> 0
A19: SYS.1～SYS.3、SWE.1～SWE.3 | B19: =COUNTIF(统计辅助!$C$2:$C$99,A19) -> 4 | C19: =COUNTIFS(统计辅助!$C$2:$C$99,A19,完成情况清单!$F$5:$F$102,"已完成") -> 0 | D19: =B19-C19-COUNTIFS(统计辅助!$C$2:$C$99,A19,完成情况清单!$F$5:$F$102,"不适用") -> 4 | E19: =IFERROR(C19/(C19+D19),0) -> 0
A20: SYS.1 | B20: =COUNTIF(统计辅助!$C$2:$C$99,A20) -> 2 | C20: =COUNTIFS(统计辅助!$C$2:$C$99,A20,完成情况清单!$F$5:$F$102,"已完成") -> 0 | D20: =B20-C20-COUNTIFS(统计辅助!$C$2:$C$99,A20,完成情况清单!$F$5:$F$102,"不适用") -> 2 | E20: =IFERROR(C20/(C20+D20),0) -> 0
A21: SYS.2 | B21: =COUNTIF(统计辅助!$C$2:$C$99,A21) -> 3 | C21: =COUNTIFS(统计辅助!$C$2:$C$99,A21,完成情况清单!$F$5:$F$102,"已完成") -> 0 | D21: =B21-C21-COUNTIFS(统计辅助!$C$2:$C$99,A21,完成情况清单!$F$5:$F$102,"不适用") -> 3 | E21: =IFERROR(C21/(C21+D21),0) -> 0
A22: SYS.3 | B22: =COUNTIF(统计辅助!$C$2:$C$99,A22) -> 3 | C22: =COUNTIFS(统计辅助!$C$2:$C$99,A22,完成情况清单!$F$5:$F$102,"已完成") -> 0 | D22: =B22-C22-COUNTIFS(统计辅助!$C$2:$C$99,A22,完成情况清单!$F$5:$F$102,"不适用") -> 3 | E22: =IFERROR(C22/(C22+D22),0) -> 0
A23: SYS.4 | B23: =COUNTIF(统计辅助!$C$2:$C$99,A23) -> 6 | C23: =COUNTIFS(统计辅助!$C$2:$C$99,A23,完成情况清单!$F$5:$F$102,"已完成") -> 0 | D23: =B23-C23-COUNTIFS(统计辅助!$C$2:$C$99,A23,完成情况清单!$F$5:$F$102,"不适用") -> 6 | E23: =IFERROR(C23/(C23+D23),0) -> 0
A24: SYS.5 | B24: =COUNTIF(统计辅助!$C$2:$C$99,A24) -> 5 | C24: =COUNTIFS(统计辅助!$C$2:$C$99,A24,完成情况清单!$F$5:$F$102,"已完成") -> 0 | D24: =B24-C24-COUNTIFS(统计辅助!$C$2:$C$99,A24,完成情况清单!$F$5:$F$102,"不适用") -> 5 | E24: =IFERROR(C24/(C24+D24),0) -> 0
A25: SWE.1 | B25: =COUNTIF(统计辅助!$C$2:$C$99,A25) -> 4 | C25: =COUNTIFS(统计辅助!$C$2:$C$99,A25,完成情况清单!$F$5:$F$102,"已完成") -> 0 | D25: =B25-C25-COUNTIFS(统计辅助!$C$2:$C$99,A25,完成情况清单!$F$5:$F$102,"不适用") -> 4 | E25: =IFERROR(C25/(C25+D25),0) -> 0
... A30: SWE.6 | B30: =COUNTIF(统计辅助!$C$2:$C$99,A30) -> 5 | C30: =COUNTIFS(统计辅助!$C$2:$C$99,A30,完成情况清单!$F$5:$F$102,"已完成") -> 0 | D30: =B30-C30-COUNTIFS(统计辅助!$C$2:$C$99,A30,完成情况清单!$F$5:$F$102,"不适用") -> 5 | E30: =IFERROR(C30/(C30+D30),0) -> 0

Sheet 统计辅助
A1: 序号 | B1: 阶段 | C1: 过程域
A2: 1 | B2: 项目初期 | C2: MAN.3
A3: 2 | B3: 项目初期 | C3: MAN.3
A4: 3 | B4: 项目初期 | C4: MAN.3
A5: 4 | B5: 项目初期 | C5: MAN.3
A6: 5 | B6: 项目初期 | C6: MAN.3
A7: 6 | B7: 项目初期 | C7: MAN.3
A8: 7 | B8: 项目初期 | C8: MAN.3
A9: 8 | B9: 项目初期 | C9: MAN.3
A10: 9 | B10: 项目初期 | C10: MAN.3
A11: 10 | B11: 项目初期 | C11: MAN.3
A12: 11 | B12: 项目初期 | C12: MAN.3
A13: 12 | B13: 项目初期 | C13: MAN.3
... A99: 98 | B99: 周期性/不固定任务 | C99: MAN.3
